#VRML_SIM R2025a utf8

EXTERNPROTO "https://raw.githubusercontent.com/cyberbotics/webots/R2025a/projects/objects/backgrounds/protos/TexturedBackground.proto"
EXTERNPROTO "https://raw.githubusercontent.com/cyberbotics/webots/R2025a/projects/objects/backgrounds/protos/TexturedBackgroundLight.proto"
EXTERNPROTO "https://raw.githubusercontent.com/cyberbotics/webots/R2025a/projects/objects/floors/protos/RectangleArena.proto"
EXTERNPROTO "https://raw.githubusercontent.com/cyberbotics/webots/R2025a/projects/vehicles/protos/abstract/VehicleWheel.proto"

WorldInfo {
}
Viewpoint {
  orientation 0.17621402565334157 -0.12365217754043481 -0.9765545331176093 4.3431111795680595
  position 0.6763168323265055 -1.6314887011642598 0.7521805827660749
}
TexturedBackground {
}
TexturedBackgroundLight {
}
RectangleArena {
  floorSize 2 2
  wallHeight 0.001
}
Robot {
  translation 1 1 1
  children [
    Emitter {
    }
    Shape {
      appearance PBRAppearance {
        baseColor 1 0 1
        roughness 0.5
      }
      geometry Sphere {
        radius 0.1
      }
    }
  ]
  name "beacon_Alpha"
}
Robot {
  translation 0 0.01 0.08
  children [
    Pose {
      translation 0.11 0 -0.0475
      children [
        BallJoint {
          jointParameters BallJointParameters {
          }
          jointParameters2 JointParameters {
          }
          jointParameters3 JointParameters {
          }
          endPoint Solid {
            children [
              Shape {
                appearance PBRAppearance {
                }
                geometry Sphere {
                  radius 0.025
                }
              }
            ]
            boundingObject Sphere {
              radius 0.025
            }
            physics Physics {
            }
          }
        }
      ]
    }
    Pose {
      translation -0.09 0 0.04
      children [
        Pose {
          translation 0 0 0.07
          children [
            Hinge2Joint {
              jointParameters HingeJointParameters {
                axis 0 0 1
              }
              jointParameters2 JointParameters {
                axis 0 1 0
              }
              device [
                RotationalMotor {
                  name "turret horizontal rotation motor"
                }
              ]
              device2 [
                RotationalMotor {
                  name "turret vertical rotation motor"
                }
              ]
              endPoint DistanceSensor {
                rotation 0 0 1 3.14159
                children [
                  Pose {
                    translation 0.05 0 -1.8366e-07
                    rotation 0 1 0 1.5708
                    children [
                      Shape {
                        appearance PBRAppearance {
                          baseColor 1 0 0
                          roughness 0.5
                          metalness 0.4
                        }
                        geometry Cone {
                          bottomRadius 0.025
                          height 0.1
                          subdivision 4
                        }
                      }
                    ]
                  }
                ]
              }
            }
          ]
        }
        Shape {
          appearance PBRAppearance {
            baseColor 0.2 0.2 0.8
            roughness 0.5
            metalness 0
          }
          geometry Box {
            size 0.05 0.05 0.1
          }
        }
      ]
    }
    Receiver {
    }
    Pose {
      translation -0.07 0 0
      children [
        Pose {
          translation 0 -0.07 0
          children [
            HingeJoint {
              jointParameters HingeJointParameters {
                axis 0 1 0
              }
              device [
                RotationalMotor {
                  name "rm_left"
                }
              ]
              endPoint Slot {
                endPoint VehicleWheel {
                  name "vehicle wheel(2)"
                  thickness 0.03
                  tireRadius 0.07
                  rimRadius 0.06
                  rimBeamWidth 0.01
                  centralInnerRadius 0.009
                  centralOuterRadius 0.013
                  rimBeamThickness 0.02
                  rimBeamOffset 0.003
                }
              }
            }
          ]
        }
        Pose {
          translation 0 0.07 0
          children [
            HingeJoint {
              jointParameters HingeJointParameters {
                axis 0 1 0
              }
              device [
                RotationalMotor {
                  name "rm_right"
                }
              ]
              endPoint Slot {
                endPoint VehicleWheel {
                  name "vehicle wheel(1)"
                  thickness 0.03
                  tireRadius 0.07
                  rimRadius 0.06
                  rimBeamWidth 0.01
                  centralInnerRadius 0.009
                  centralOuterRadius 0.013
                  rimBeamThickness 0.02
                  rimBeamOffset 0.003
                }
              }
            }
          ]
        }
      ]
    }
    Shape {
      appearance PBRAppearance {
        baseColor 0.2 0.2 0.8
        roughness 0.5
        metalness 0
      }
      geometry Box {
        size 0.3 0.1 0.03
      }
    }
    Compass {
    }
  ]
  name "chariot"
  boundingObject Box {
    size 0.3 0.1 0.03
  }
  physics Physics {
  }
}
Robot {
  name "Supervisor"
  supervisor TRUE
}
