#VRML_SIM R2025a utf8

EXTERNPROTO "https://raw.githubusercontent.com/cyberbotics/webots/R2025a/projects/objects/backgrounds/protos/TexturedBackground.proto"
EXTERNPROTO "https://raw.githubusercontent.com/cyberbotics/webots/R2025a/projects/objects/backgrounds/protos/TexturedBackgroundLight.proto"
EXTERNPROTO "https://raw.githubusercontent.com/cyberbotics/webots/R2025a/projects/objects/floors/protos/RectangleArena.proto"
EXTERNPROTO "https://raw.githubusercontent.com/cyberbotics/webots/R2025a/projects/vehicles/protos/abstract/VehicleWheel.proto"

WorldInfo {
}
Viewpoint {
  orientation -0.5048420129700193 -0.2614073600089879 0.8226789981964474 3.947004950476982
  position 0.504363687969002 0.8224996661447969 1.7631213075306544
}
TexturedBackground {
}
TexturedBackgroundLight {
}
RectangleArena {
}
Robot {
  translation 1 1 1
  children [
    Emitter {
    }
    Shape {
      appearance PBRAppearance {
        baseColor 1 0 1
        roughness 0.5
      }
      geometry Sphere {
        radius 0.1
      }
    }
  ]
  name "beacon_Alpha"
}
Robot {
  translation 0 -0.01 0.1
  children [
    Receiver {
    }
    Pose {
      translation -0.07 0 0
      children [
        Pose {
          translation 0 -0.07 0
          children [
            HingeJoint {
              jointParameters HingeJointParameters {
                axis 0 1 0
              }
              device [
                RotationalMotor {
                  name "rm_left"
                }
              ]
              endPoint Slot {
                endPoint VehicleWheel {
                  name "vehicle wheel(2)"
                  thickness 0.03
                  tireRadius 0.07
                  rimRadius 0.06
                  rimBeamWidth 0.01
                  centralInnerRadius 0.009
                  centralOuterRadius 0.013
                  rimBeamThickness 0.02
                  rimBeamOffset 0.003
                }
              }
            }
          ]
        }
        Pose {
          translation 0 0.07 0
          children [
            HingeJoint {
              jointParameters HingeJointParameters {
                axis 0 1 0
              }
              device [
                RotationalMotor {
                  name "rm_right"
                }
              ]
              endPoint Slot {
                endPoint VehicleWheel {
                  name "vehicle wheel(1)"
                  thickness 0.03
                  tireRadius 0.07
                  rimRadius 0.06
                  rimBeamWidth 0.01
                  centralInnerRadius 0.009
                  centralOuterRadius 0.013
                  rimBeamThickness 0.02
                  rimBeamOffset 0.003
                }
              }
            }
          ]
        }
      ]
    }
    Shape {
      appearance PBRAppearance {
        baseColor 0.2 0.2 0.8
        roughness 0.5
        metalness 0
      }
      geometry Box {
        size 0.3 0.1 0.03
      }
    }
    Compass {
    }
  ]
  name "chariot"
  boundingObject Box {
    size 0.3 0.1 0.03
  }
  physics Physics {
  }
}
